Workbook

Sheet Datos
A1: 0 | B1: 1 | C1: 2 | D1: 3 | E1: 4 | F1: 5 | G1: 6 | H1: 7 | I1: 8 | J1: 9 | K1: 10 | L1: 11 | M1: 12 | N1: 13 | O1: 14 | P1: 15 | Q1: 16 | R1: 17 | S1: 18 | T1: 19 | U1: 20 | V1: 21 | W1: 22 | X1: 23 | Y1: 24 | Z1: 25 | AA1: 26 | AB1: 27 | AC1: 28 | AD1: 29 | AE1: 30 | AF1: 31 | AG1: 32 | AH1: 33 | AI1: 34 | AJ1: 35 | AK1: 36 | AL1: 37 | AM1: 38 | AN1: 39 | AO1: 40 | AP1: 41 | AQ1: 42 | AR1: 43 | AS1: 44 | AT1: 45 | AU1: 46 | AV1: 47
A2: Clave ubic | B2: Clave | C2: Sem | D2: Ubicación | E2: Clasif | F2: Packing | G2: Alm | H2: J | I2: A | J2: SX | K2: B | L2: X | M2: C | N2: 1ra | O2: D | P2: 2da | Q2: E | R2: 3ra | S2: F | T2: 4ta | U2: G | V2: SM | W2: H | X2: SS | Y2: I | Z2: ST | AA2: J | AB2: TM | AC2: K | AD2: TS | AE2: L | AF2: TT | AG2: M | AH2: LM | AI2: N | AJ2: O | AK2: P | AL2: total maq | AM2: Q | AN2: tot no maq | AO2: R | AP2: Total Gral | AQ2: SUCIO | AR2: ST/CAJA | AS2: TRIZADO | AT2: TT/CAJA | AU2: LIQUIDO | AV2: LM/CAJA
A3: =+CONCATENATE(D3,C3) -> Calera1 | B3: =+CONCATENATE(G3,C3) -> CA3A1 | C3: 1 | D3: Calera | E3: color | F3: Packing 1 Color | G3: CA3A | H3: 4440 | J3: 14400 | L3: 0 | N3: 47700 | P3: 540 | V3: 984 | X3: 750 | Z3: 1734 | AB3: 714 | AD3: 900 | AF3: 1614 | AH3: 402 | AL3: 69180 | AN3: 1650 | AP3: 70830 | AQ3: =+Z3/AP3 -> 0.024481152 | AR3: =+Z3/180 -> 9.6333333 | AS3: =+AF3/AP3 -> 0.022786955 | AT3: =+AF3/180 -> 8.9666667 | AU3: =+AH3/AP3 -> 0.0056755612 | AV3: =+AH3/180 -> 2.2333333
A4: =+CONCATENATE(D4,C4) -> Calera1 | B4: =+CONCATENATE(G4,C4) -> CA3B1 | C4: 1 | D4: Calera | E4: color | F4: Packing 1 Color | G4: CA3B | H4: 1200 | J4: 11740 | L4: 24600 | N4: 30240 | P4: 6840 | V4: 1869 | X4: 930 | Z4: 2799 | AB4: 1098 | AD4: 810 | AF4: 1908 | AH4: 473 | AL4: 78060 | AN4: 1740 | AP4: 79800 | AQ4: =+Z4/AP4 -> 0.035075188 | AR4: =+Z4/180 -> 15.55 | AS4: =+AF4/AP4 -> 0.023909774 | AT4: =+AF4/180 -> 10.6 | AU4: =+AH4/AP4 -> 0.0059273183 | AV4: =+AH4/180 -> 2.6277778
A5: =+CONCATENATE(D5,C5) -> Calera1 | B5: =+CONCATENATE(G5,C5) -> CA3BB1 | C5: 1 | D5: Calera | E5: blanco | F5: Packing 1 Color | G5: CA3BB | H5: 720 | J5: 1980 | L5: 3780 | N5: 540 | P5: 0 | V5: 210 | X5: 150 | Z5: 360 | AB5: 90 | AD5: 60 | AF5: 150 | AH5: 90 | AL5: 7410 | AN5: 210 | AP5: 7620 | AQ5: =+Z5/AP5 -> 0.047244094 | AR5: =+Z5/180 -> 2 | AS5: =+AF5/AP5 -> 0.019685039 | AT5: =+AF5/180 -> 0.83333333 | AU5: =+AH5/AP5 -> 0.011811024 | AV5: =+AH5/180 -> 0.5
A6: =+CONCATENATE(D6,C6) -> Calera1 | B6: =+CONCATENATE(G6,C6) -> CAP1A1 | C6: 1 | D6: Calera | E6: color | F6: Packing 1 Color | G6: CAP1A | H6: 0 | J6: 0 | L6: 0 | N6: 16740 | P6: 6120 | V6: 840 | X6: 570 | Z6: 1410 | AB6: 60 | AD6: 0 | AF6: 60 | AH6: 270 | AL6: 24030 | AN6: 570 | AP6: 24600 | AQ6: =+Z6/AP6 -> 0.057317073 | AR6: =+Z6/180 -> 7.8333333 | AS6: =+AF6/AP6 -> 0.0024390244 | AT6: =+AF6/180 -> 0.33333333 | AU6: =+AH6/AP6 -> 0.01097561 | AV6: =+AH6/180 -> 1.5
A7: =+CONCATENATE(D7,C7) -> Calera1 | B7: =+CONCATENATE(G7,C7) -> CAP1B1 | C7: 1 | D7: Calera | E7: color | F7: Packing 1 Color | G7: CAP1B | H7: 240 | J7: 0 | L7: 9600 | N7: 4860 | P7: 360 | V7: 360 | X7: 180 | Z7: 540 | AB7: 90 | AD7: 0 | AF7: 90 | AH7: 210 | AL7: 15720 | AN7: 180 | AP7: 15900 | AQ7: =+Z7/AP7 -> 0.033962264 | AR7: =+Z7/180 -> 3 | AS7: =+AF7/AP7 -> 0.0056603774 | AT7: =+AF7/180 -> 0.5 | AU7: =+AH7/AP7 -> 0.013207547 | AV7: =+AH7/180 -> 1.1666667
A8: =+CONCATENATE(D8,C8) -> Calera1 | B8: =+CONCATENATE(G8,C8) -> CAP1c1 | C8: 1 | D8: Calera | E8: color | F8: Packing 1 Color | G8: CAP1c | H8: 720 | J8: 0 | L8: 3500 | N8: 14040 | P8: 5940 | V8: 318 | X8: 420 | Z8: 738 | AB8: 336 | AD8: 0 | AF8: 336 | AH8: 46 | AL8: 24900 | AN8: 420 | AP8: 25320 | AQ8: =+Z8/AP8 -> 0.029146919 | AR8: =+Z8/180 -> 4.1 | AS8: =+AF8/AP8 -> 0.013270142 | AT8: =+AF8/180 -> 1.8666667 | AU8: =+AH8/AP8 -> 0.0018167457 | AV8: =+AH8/180 -> 0.25555556
A9: =+CONCATENATE(D9,C9) -> Pichidegua1 | B9: =+CONCATENATE(G9,C9) -> PICH1A1 | C9: 1 | D9: Pichidegua | F9: Packing 1 Blanco | G9: PICH1A | AQ9: 0 | AR9: =+Z9/180 -> 0 | AS9: 0 | AT9: =+AF9/180 -> 0 | AU9: 0 | AV9: =+AH9/180 -> 0
A10: =+CONCATENATE(D10,C10) -> Pichidegua1 | B10: =+CONCATENATE(G10,C10) -> PICH2A1 | C10: 1 | D10: Pichidegua | E10: color | F10: Packing 1 Blanco | G10: PICH2A | H10: 360 | J10: 10980 | L10: 81600 | N10: 52920 | P10: 37260 | R10: 0 | V10: 4080 | X10: 18450 | Z10: 22530 | AB10: 2979 | AD10: 2100 | AF10: 5079 | AH10: 1661 | AL10: 191840 | AN10: 20550 | AP10: 212390 | AQ10: =+Z10/AP10 -> 0.10607844 | AR10: =+Z10/180 -> 125.16667 | AS10: =+AF10/AP10 -> 0.023913555 | AT10: =+AF10/180 -> 28.216667 | AU10: =+AH10/AP10 -> 0.0078205189 | AV10: =+AH10/180 -> 9.2277778
A11: =+CONCATENATE(D11,C11) -> Pichidegua1 | B11: =+CONCATENATE(G11,C11) -> PICH3A1 | C11: 1 | D11: Pichidegua | E11: blanco | F11: Packing 3 | G11: PICH3A | H11: 3600 | J11: 27540 | L11: 204020 | N11: 137340 | P11: 6840 | R11: 0 | V11: 23760 | X11: 0 | Z11: 23760 | AB11: 1980 | AD11: 0 | AF11: 1980 | AH11: 300 | AL11: 405380 | AN11: 0 | AP11: 405380 | AQ11: =+Z11/AP11 -> 0.058611673 | AR11: =+Z11/180 -> 132 | AS11: =+AF11/AP11 -> 0.0048843061 | AT11: =+AF11/180 -> 11 | AU11: =+AH11/AP11 -> 0.00074004638 | AV11: =+AH11/180 -> 1.6666667
A12: =+CONCATENATE(D12,C12) -> Pichidegua1 | B12: =+CONCATENATE(G12,C12) -> PICH4A1 | C12: 1 | D12: Pichidegua | E12: blanco | F12: Packing 4 | G12: PICH4A | H12: 5880 | J12: 32400 | L12: 93420 | N12: 36360 | P12: 9000 | R12: 0 | V12: 33480 | X12: 0 | Z12: 33480 | AB12: 4500 | AD12: 0 | AF12: 4500 | AH12: 1100 | AL12: 216140 | AN12: 0 | AP12: 216140 | AQ12: =+Z12/AP12 -> 0.1548996 | AR12: =+Z12/180 -> 186 | AS12: =+AF12/AP12 -> 0.020819839 | AT12: =+AF12/180 -> 25 | AU12: =+AH12/AP12 -> 0.005089294 | AV12: =+AH12/180 -> 6.1111111
A13: =+CONCATENATE(D13,C13) -> Pichidegua1 | B13: =+CONCATENATE(G13,C13) -> PICH5A1 | C13: 1 | D13: Pichidegua | E13: blanco | F13: Packing 5 | G13: PICH5A | H13: 9480 | J13: 7380 | L13: 7020 | N13: 132480 | P13: 145440 | R13: 8100 | V13: 7200 | X13: 0 | Z13: 7200 | AB13: 1800 | AD13: 0 | AF13: 1800 | AH13: 560 | AL13: 319460 | AN13: 0 | AP13: 319460 | AQ13: =+Z13/AP13 -> 0.022538033 | AR13: =+Z13/180 -> 40 | AS13: =+AF13/AP13 -> 0.0056345082 | AT13: =+AF13/180 -> 10 | AU13: =+AH13/AP13 -> 0.0017529581 | AV13: =+AH13/180 -> 3.1111111
A14: =+CONCATENATE(D14,C14) -> Pichidegua1 | B14: =+CONCATENATE(G14,C14) -> PICH1B1 | C14: 1 | D14: Pichidegua | F14: Packing 1 Blanco | G14: PICH1B | AQ14: 0 | AR14: =+Z14/180 -> 0 | AS14: 0 | AT14: =+AF14/180 -> 0 | AU14: 0 | AV14: =+AH14/180 -> 0
A15: =+CONCATENATE(D15,C15) -> Pichidegua1 | B15: =+CONCATENATE(G15,C15) -> PICH2B1 | C15: 1 | D15: Pichidegua | E15: blanco | F15: Packing 1 Blanco | G15: PICH2B | AQ15: 0 | AR15: =+Z15/180 -> 0 | AS15: 0 | AT15: =+AF15/180 -> 0 | AU15: 0 | AV15: =+AH15/180 -> 0
A16: =+CONCATENATE(D16,C16) -> Pichidegua1 | B16: =+CONCATENATE(G16,C16) -> PICH3B1 | C16: 1 | D16: Pichidegua | E16: blanco | F16: Packing 3 | G16: PICH3B | AQ16: 0 | AR16: =+Z16/180 -> 0 | AS16: 0 | AT16: =+AF16/180 -> 0 | AU16: 0 | AV16: =+AH16/180 -> 0
A17: =+CONCATENATE(D17,C17) -> Pichidegua1 | B17: =+CONCATENATE(G17,C17) -> PICH4B1 | C17: 1 | D17: Pichidegua | E17: blanco | F17: Packing 4 | G17: PICH4B | AQ17: 0 | AR17: =+Z17/180 -> 0 | AS17: 0 | AT17: =+AF17/180 -> 0 | AU17: 0 | AV17: =+AH17/180 -> 0
A18: =+CONCATENATE(D18,C18) -> Pichidegua1 | B18: =+CONCATENATE(G18,C18) -> PICH5B1 | C18: 1 | D18: Pichidegua | E18: blanco | F18: Packing 5 | G18: PICH5B | H18: 8520 | J18: 59040 | L18: 100980 | N18: 33660 | P18: 3780 | R18: 0 | V18: 27360 | X18: 0 | Z18: 27360 | AB18: 3780 | AD18: 0 | AF18: 3780 | AH18: 740 | AL18: 237860 | AN18: 0 | AP18: 237860 | AQ18: =+Z18/AP18 -> 0.11502565 | AR18: =+Z18/180 -> 152 | AS18: =+AF18/AP18 -> 0.015891701 | AT18: =+AF18/180 -> 21 | AU18: =+AH18/AP18 -> 0.0031110737 | AV18: =+AH18/180 -> 4.1111111
A19: =+CONCATENATE(D19,C19) -> Pichidegua1 | B19: =+CONCATENATE(G19,C19) -> PICH3C1 | C19: 1 | D19: Pichidegua | E19: blanco | F19: Packing 3 | G19: PICH3C | H19: 10680 | J19: 45180 | L19: 133580 | N19: 48780 | P19: 3240 | R19: 0 | V19: 23400 | X19: 0 | Z19: 23400 | AB19: 3780 | AD19: 0 | AF19: 3780 | AH19: 360 | AL19: 269000 | AN19: 0 | AP19: 269000 | AQ19: =+Z19/AP19 -> 0.086988848 | AR19: =+Z19/180 -> 130 | AS19: =+AF19/AP19 -> 0.014052045 | AT19: =+AF19/180 -> 21 | AU19: =+AH19/AP19 -> 0.00133829 | AV19: =+AH19/180 -> 2
A20: =+CONCATENATE(D20,C20) -> Pichidegua1 | B20: =+CONCATENATE(G20,C20) -> PICH5C1 | C20: 1 | D20: Pichidegua | E20: blanco | F20: Packing 5 | G20: PICH5C | AQ20: 0 | AR20: =+Z20/180 -> 0 | AS20: 0 | AT20: =+AF20/180 -> 0 | AU20: 0 | AV20: =+AH20/180 -> 0
A21: =+CONCATENATE(D21,C21) -> Pichidegua1 | B21: =+CONCATENATE(G21,C21) -> PICH5D1 | C21: 1 | D21: Pichidegua | E21: blanco | F21: Packing 5 | G21: PICH5D | H21: 5760 | J21: 4500 | L21: 97200 | N21: 180000 | P21: 21600 | R21: 0 | V21: 18540 | X21: 0 | Z21: 18540 | AB21: 2700 | AD21: 0 | AF21: 2700 | AH21: 620 | AL21: 330920 | AN21: 0 | AP21: 330920 | AQ21: =+Z21/AP21 -> 0.056025626 | AR21: =+Z21/180 -> 103 | AS21: =+AF21/AP21 -> 0.0081590717 | AT21: =+AF21/180 -> 15 | AU21: =+AH21/AP21 -> 0.0018735646 | AV21: =+AH21/180 -> 3.4444444
A22: =+CONCATENATE(D22,C22) -> Pichidegua1 | B22: =+CONCATENATE(G22,C22) -> PICH1Aco1 | C22: 1 | D22: Pichidegua | E22: color | F22: Packing 1 Color | G22: PICH1Aco | H22: 2160 | J22: 900 | L22: 6900 | N22: 52380 | P22: 5940 | R22: 0 | V22: 2760 | X22: 4680 | Z22: 7440 | AB22: 819 | AD22: 840 | AF22: 1659 | AH22: 561 | AL22: 72420 | AN22: 5520 | AP22: 77940 | AQ22: =+Z22/AP22 -> 0.095458045 | AR22: =+Z22/180 -> 41.333333 | AS22: =+AF22/AP22 -> 0.021285604 | AT22: =+AF22/180 -> 9.2166667 | AU22: =+AH22/AP22 -> 0.0071978445 | AV22: =+AH22/180 -> 3.1166667
A23: =+CONCATENATE(D23,C23) -> Pichidegua1 | B23: =+CONCATENATE(G23,C23) -> PICH1Aco21 | C23: 1 | D23: Pichidegua | E23: color | F23: Packing 1 Color | G23: PICH1Aco2 | H23: 3720 | J23: 14400 | L23: 12420 | N23: 25020 | P23: 360 | R23: 0 | V23: 1350 | X23: 2580 | Z23: 3930 | AB23: 720 | AD23: 1440 | AF23: 2160 | AH23: 1050 | AL23: 59040 | AN23: 4020 | AP23: 63060 | AQ23: =+Z23/AP23 -> 0.062321598 | AR23: =+Z23/180 -> 21.833333 | AS23: =+AF23/AP23 -> 0.034253092 | AT23: =+AF23/180 -> 12 | AU23: =+AH23/AP23 -> 0.016650809 | AV23: =+AH23/180 -> 5.8333333
A24: =+CONCATENATE(D24,C24) -> Pichidegua1 | B24: =+CONCATENATE(G24,C24) -> PICH1Bco1 | C24: 1 | D24: Pichidegua | E24: color | F24: Packing 1 Color | G24: PICH1Bco | H24: 600 | J24: 180 | L24: 3200 | N24: 12780 | P24: 10800 | R24: 0 | V24: 498 | X24: 330 | Z24: 828 | AB24: 255 | AD24: 60 | AF24: 315 | AH24: 127 | AL24: 28440 | AN24: 390 | AP24: 28830 | AQ24: =+Z24/AP24 -> 0.028720083 | AR24: =+Z24/180 -> 4.6 | AS24: =+AF24/AP24 -> 0.010926119 | AT24: =+AF24/180 -> 1.75 | AU24: =+AH24/AP24 -> 0.0044051335 | AV24: =+AH24/180 -> 0.70555556
A25: =+CONCATENATE(D25,C25) -> Pichidegua1 | B25: =+CONCATENATE(G25,C25) -> PICH2BCO1 | C25: 1 | D25: Pichidegua | E25: color | F25: Packing 1 Color | G25: PICH2BCO | H25: 10440 | J25: 16560 | L25: 23220 | N25: 12420 | P25: 540 | R25: 0 | V25: 1548 | X25: 1260 | Z25: 2808 | AB25: 1650 | AD25: 750 | AF25: 2400 | AH25: 2372 | AL25: 68750 | AN25: 2010 | AP25: 70760 | AQ25: =+Z25/AP25 -> 0.039683437 | AR25: =+Z25/180 -> 15.6 | AS25: =+AF25/AP25 -> 0.033917467 | AT25: =+AF25/180 -> 13.333333 | AU25: =+AH25/AP25 -> 0.033521764 | AV25: =+AH25/180 -> 13.177778
A26: =+CONCATENATE(D26,C26) -> Pichidegua1 | B26: =+CONCATENATE(G26,C26) -> PICH4Bco1 | C26: 1 | D26: Pichidegua | E26: color | F26: Packing 4 | G26: PICH4Bco | AQ26: 0 | AR26: =+Z26/180 -> 0 | AS26: 0 | AT26: =+AF26/180 -> 0 | AU26: 0 | AV26: =+AH26/180 -> 0
A27: =+CONCATENATE(D27,C27) -> Pichidegua1 | B27: =+CONCATENATE(G27,C27) -> PICH5Aco1 | C27: 1 | D27: Pichidegua | E27: color | F27: Packing 5 | G27: PICH5Aco | H27: 7200 | J27: 12960 | L27: 23760 | N27: 58680 | P27: 28260 | R27: 1260 | V27: 4950 | X27: 0 | Z27: 4950 | AB27: 2160 | AD27: 0 | AF27: 2160 | AH27: 500 | AL27: 139730 | AN27: 0 | AP27: 139730 | AQ27: =+Z27/AP27 -> 0.035425463 | AR27: =+Z27/180 -> 27.5 | AS27: =+AF27/AP27 -> 0.015458384 | AT27: =+AF27/180 -> 12 | AU27: =+AH27/AP27 -> 0.0035783296 | AV27: =+AH27/180 -> 2.7777778
A28: =+CONCATENATE(D28,C28) -> Pichidegua1 | B28: =+CONCATENATE(G28,C28) -> PICH5Bco1 | C28: 1 | D28: Pichidegua | E28: color | F28: Packing 5 | G28: PICH5Bco | H28: 3960 | J28: 13860 | L28: 15480 | N28: 56160 | P28: 0 | R28: 0 | V28: 5490 | X28: 0 | Z28: 5490 | AB28: 1800 | AD28: 0 | AF28: 1800 | AH28: 640 | AL28: 97390 | AN28: 0 | AP28: 97390 | AQ28: =+Z28/AP28 -> 0.056371291 | AR28: =+Z28/180 -> 30.5 | AS28: =+AF28/AP28 -> 0.01848239 | AT28: =+AF28/180 -> 10 | AU28: =+AH28/AP28 -> 0.0065715166 | AV28: =+AH28/180 -> 3.5555556
A29: =+CONCATENATE(D29,C29) -> Pichidegua1 | B29: =+CONCATENATE(G29,C29) -> PICH5Cco1 | C29: 1 | D29: Pichidegua | E29: color | F29: Packing 5 | G29: PICH5Cco | H29: 0 | J29: 0 | L29: 0 | N29: 0 | P29: 0 | R29: 0 | V29: 0 | X29: 0 | Z29: 0 | AB29: 0 | AD29: 0 | AF29: 0 | AH29: 0 | AL29: 0 | AN29: 0 | AP29: 0 | AQ29: 0 | AR29: =+Z29/180 -> 0 | AS29: 0 | AT29: =+AF29/180 -> 0 | AU29: 0 | AV29: =+AH29/180 -> 0
A30: =+CONCATENATE(D30,C30) -> 1 | B30: =+CONCATENATE(G30,C30) -> Lavado1 | C30: 1 | G30: Lavado | H30: 5040 | J30: 14760 | L30: 41040 | N30: 34200 | P30: 13680 | R30: 1800 | AL30: 110520 | AP30: 110520 | AQ30: =+Z30/AP30 -> 0 | AR30: =+Z30/180 -> 0 | AS30: =+AF30/AP30 -> 0 | AT30: =+AF30/180 -> 0 | AU30: =+AH30/AP30 -> 0 | AV30: =+AH30/180 -> 0
A31: =+CONCATENATE(D31,C31) -> Calera2 | B31: =+CONCATENATE(G31,C31) -> CA3A2 | C31: 2 | D31: Calera | E31: color | F31: Packing 1 Color | G31: CA3A | H31: 3000 | J31: 12060 | L31: 15480 | N31: 16920 | P31: 360 | R31: 0 | V31: 1320 | X31: 630 | Z31: 1950 | AB31: 540 | AD31: 840 | AF31: 1380 | AH31: 80 | AL31: 49760 | AN31: 1470 | AP31: 51230 | AQ31: =+Z31/AP31 -> 0.038063635 | AR31: =+Z31/180 -> 10.833333 | AS31: =+AF31/AP31 -> 0.026937341 | AT31: =+AF31/180 -> 7.6666667 | AU31: =+AH31/AP31 -> 0.001561585 | AV31: =+AH31/180 -> 0.44444444
A32: =+CONCATENATE(D32,C32) -> Calera2 | B32: =+CONCATENATE(G32,C32) -> CA3B2 | C32: 2 | D32: Calera | E32: color | F32: Packing 1 Color | G32: CA3B | H32: 600 | J32: 6480 | L32: 0 | N32: 39060 | P32: 2160 | R32: 0 | V32: 2676 | X32: 810 | Z32: 3486 | AB32: 702 | AD32: 840 | AF32: 1542 | AH32: 762 | AL32: 52440 | AN32: 1650 | AP32: 54090 | AQ32: =+Z32/AP32 -> 0.064448142 | AR32: =+Z32/180 -> 19.366667 | AS32: =+AF32/AP32 -> 0.028508042 | AT32: =+AF32/180 -> 8.5666667 | AU32: =+AH32/AP32 -> 0.014087632 | AV32: =+AH32/180 -> 4.2333333
A33: =+CONCATENATE(D33,C33) -> Calera2 | B33: =+CONCATENATE(G33,C33) -> CA3BB2 | C33: 2 | D33: Calera | E33: blanco | F33: Packing 1 Color | G33: CA3BB | H33: 480 | J33: 1260 | L33: 1080 | N33: 900 | P33: 0 | R33: 0 | V33: 183 | X33: 120 | Z33: 303 | AB33: 78 | AD33: 60 | AF33: 138 | AH33: 39 | AL33: 4020 | AN33: 180 | AP33: 4200 | AQ33: =+Z33/AP33 -> 0.072142857 | AR33: =+Z33/180 -> 1.6833333 | AS33: =+AF33/AP33 -> 0.032857143 | AT33: =+AF33/180 -> 0.76666667 | AU33: =+AH33/AP33 -> 0.0092857143 | AV33: =+AH33/180 -> 0.21666667
A34: =+CONCATENATE(D34,C34) -> Calera2 | B34: =+CONCATENATE(G34,C34) -> CAP1A2 | C34: 2 | D34: Calera | E34: color | F34: Packing 1 Color | G34: CAP1A | H34: 840 | J34: 0 | L34: 4000 | N34: 10980 | P34: 5400 | R34: 0 | V34: 1170 | X34: 930 | Z34: 2100 | AB34: 228 | AD34: 0 | AF34: 228 | AH34: 602 | AL34: 23220 | AN34: 930 | AP34: 24150 | AQ34: =+Z34/AP34 -> 0.086956522 | AR34: =+Z34/180 -> 11.666667 | AS34: =+AF34/AP34 -> 0.0094409938 | AT34: =+AF34/180 -> 1.2666667 | AU34: =+AH34/AP34 -> 0.024927536 | AV34: =+AH34/180 -> 3.3444444
A35: =+CONCATENATE(D35,C35) -> Calera2 | B35: =+CONCATENATE(G35,C35) -> CAP1B2 | C35: 2 | D35: Calera | E35: color | F35: Packing 1 Color | G35: CAP1B | H35: 1200 | J35: 900 | L35: 12640 | N35: 19080 | P35: 1260 | R35: 0 | V35: 954 | X35: 270 | Z35: 1224 | AB35: 300 | AD35: 0 | AF35: 300 | AH35: 146 | AL35: 36480 | AN35: 270 | AP35: 36750 | AQ35: =+Z35/AP35 -> 0.033306122 | AR35: =+Z35/180 -> 6.8 | AS35: =+AF35/AP35 -> 0.0081632653 | AT35: =+AF35/180 -> 1.6666667 | AU35: =+AH35/AP35 -> 0.0039727891 | AV35: =+AH35/180 -> 0.81111111
A36: =+CONCATENATE(D36,C36) -> Calera2 | B36: =+CONCATENATE(G36,C36) -> CAP1c2 | C36: 2 | D36: Calera | E36: color | F36: Packing 1 Color | G36: CAP1c | H36: 1680 | J36: 360 | L36: 8240 | N36: 8820 | P36: 5040 | R36: 180 | V36: 1419 | X36: 510 | Z36: 1929 | AB36: 309 | AD36: 0 | AF36: 309 | AH36: 0 | AL36: 26048 | AN36: 510 | AP36: 26558 | AQ36: =+Z36/AP36 -> 0.072633481 | AR36: =+Z36/180 -> 10.716667 | AS36: =+AF36/AP36 -> 0.011634912 | AT36: =+AF36/180 -> 1.7166667 | AU36: =+AH36/AP36 -> 0 | AV36: =+AH36/180 -> 0
A37: =+CONCATENATE(D37,C37) -> Pichidegua2 | B37: =+CONCATENATE(G37,C37) -> PICH1A2 | C37: 2 | D37: Pichidegua | F37: Packing 1 Blanco | G37: PICH1A | AQ37: 0 | AR37: =+Z37/180 -> 0 | AS37: 0 | AT37: =+AF37/180 -> 0 | AU37: 0 | AV37: =+AH37/180 -> 0
A38: =+CONCATENATE(D38,C38) -> Pichidegua2 | B38: =+CONCATENATE(G38,C38) -> PICH2A2 | C38: 2 | D38: Pichidegua | E38: color | F38: Packing 1 Blanco | G38: PICH2A | H38: 2760 | J38: 41520 | L38: 243920 | N38: 173700 | P38: 9540 | R38: 0 | T38: 0 | V38: 22584 | X38: 0 | Z38: 22584 | AB38: 6921 | AD38: 0 | AF38: 6921 | AH38: 1315 | AL38: 502260 | AN38: 0 | AP38: 502260 | AQ38: =+Z38/AP38 -> 0.044964759 | AR38: =+Z38/180 -> 125.46667 | AS38: =+AF38/AP38 -> 0.013779716 | AT38: =+AF38/180 -> 38.45 | AU38: =+AH38/AP38 -> 0.0026181659 | AV38: =+AH38/180 -> 7.3055556
A39: =+CONCATENATE(D39,C39) -> Pichidegua2 | B39: =+CONCATENATE(G39,C39) -> PICH3A2 | C39: 2 | D39: Pichidegua | E39: blanco | F39: Packing 3 | G39: PICH3A | H39: 2280 | J39: 20520 | L39: 159400 | N39: 115380 | P39: 6480 | R39: 0 | T39: 0 | V39: 20340 | X39: 0 | Z39: 20340 | AB39: 2160 | AD39: 0 | AF39: 2160 | AH39: 280 | AL39: 326840 | AN39: 0 | AP39: 326840 | AQ39: =+Z39/AP39 -> 0.062232285 | AR39: =+Z39/180 -> 113 | AS39: =+AF39/AP39 -> 0.0066087382 | AT39: =+AF39/180 -> 12 | AU39: =+AH39/AP39 -> 0.00085668829 | AV39: =+AH39/180 -> 1.5555556
A40: =+CONCATENATE(D40,C40) -> Pichidegua2 | B40: =+CONCATENATE(G40,C40) -> PICH4A2 | C40: 2 | D40: Pichidegua | E40: blanco | F40: Packing 4 | G40: PICH4A | H40: 3000 | J40: 15660 | L40: 33300 | N40: 13860 | P40: 3060 | R40: 0 | T40: 0 | V40: 23940 | X40: 0 | Z40: 23940 | AB40: 42120 | AD40: 0 | AF40: 42120 | AH40: 520 | AL40: 135460 | AN40: 0 | AP40: 135460 | AQ40: =+Z40/AP40 -> 0.17673114 | AR40: =+Z40/180 -> 133 | AS40: =+AF40/AP40 -> 0.3109405 | AT40: =+AF40/180 -> 234 | AU40: =+AH40/AP40 -> 0.0038387716 | AV40: =+AH40/180 -> 2.8888889
...

Sheet TD
A1: Sem | B1: 52
A3: Etiquetas de fila | B3: SUCIO PACKING | C3: TRIZADO PACKING | D3: LIQUIDO PACKING
A4: Packing 1 Color | B4: 0.047004838 | C4: 0.018883207 | D4: 0.010048376
A5: Packing 1 Blanco | B5: 0.039148086 | C5: 0.022164583 | D5: 0.0060929243
A6: Packing 3 | B6: 0.05659544 | C6: 0.0054891899 | D6: 0.0044165896
A7: Packing 4 | B7: 0.062530834 | C7: 0.022200296 | D7: 0.0094967933
A8: Packing 5 | B8: 0.056337001 | C8: 0.010768378 | D8: 0.004216885
A9: Total general | B9: 0.053973022 | C9: 0.011815926 | D9: 0.0054012947
A12: Sem | B12: 52
A14: Etiquetas de fila | B14: Suma de Total Sucio | C14: Suma de Total Trizado | D14: Suma de Total Liquido
A15: Calera52 | B15: 0.067770352 | C15: 0.024027947 | D15: 0.016747671
A16: Pichidegua52 | B16: 0.053527305 | C16: 0.011421422 | D16: 0.0050347546
A17: 52 | B17: 0 | C17: 0 | D17: 0
A18: Total general | B18: 0.051856317 | C18: 0.011352531 | D18: 0.0051894676
A21: Sem | B21: 52
A23: Etiquetas de fila | B23: % J | C23: % S | D23: % X | E23: % 1ra | F23: % 2da | G23: %3ra | H23: %4ta | I23: %SM | J23: %SS | K23: %ST | L23: %TM | M23: %TS | N23: %TT | O23: %L
A24: Calera52 | B24: 0.047387606 | C24: 0.14216282 | D24: 0.34528149 | E24: 0.32442284 | F24: 0.030376671 | G24: 0.0018226002 | H24: 0 | I24: 0.063213852 | J24: 0.0045565006 | K24: 0.067770352 | L24: 0.016433779 | M24: 0.0075941677 | N24: 0.024027947 | O24: 0.016747671
A25: Pichidegua52 | B25: 0.024493401 | C25: 0.11855486 | D25: 0.3221628 | E25: 0.37746921 | F25: 0.087336245 | G25: 0 | H25: 0 | I25: 0.05248712 | J25: 0.0010401845 | K25: 0.053527305 | L25: 0.011028899 | M25: 0.00039252245 | N25: 0.011421422 | O25: 0.0050347546
A26: 52 | B26: 0.040055892 | C26: 0.12296227 | D26: 0.39823009 | E26: 0.36050303 | F26: 0.072659525 | G26: 0.0055891942 | H26: 0 | I26: 0 | J26: 0 | K26: 0 | L26: 0 | M26: 0 | N26: 0 | O26: 0
A27: Total general | B27: 0.025792074 | C27: 0.11943752 | D27: 0.32584109 | E27: 0.37520892 | F27: 0.085048086 | G27: 0.00027399512 | H27: 0 | I27: 0.050751203 | J27: 0.0011051137 | K27: 0.051856317 | L27: 0.010758875 | M27: 0.0005936561 | N27: 0.011352531 | O27: 0.0051894676
A29: Sem | B29: 52
A31: Etiquetas de fila | B31: J | C31: SX | D31: X | E31: 1ra | F31: 2da | G31: 3ra | H31: 4ta | I31: SM | J31: SS | K31: ST | L31: TM | M31: TS | N31: TT | O31: LM
A32: Calera52 | B32: 4680 | C32: 14040 | D32: 34100 | E32: 32040 | F32: 3000 | G32: 180 | H32: 0 | I32: 6243 | J32: 450 | K32: 6693 | L32: 1623 | M32: 750 | N32: 2373 | O32: 1654
A33: Pichidegua52 | B33: 74880 | C33: 362440 | D33: 984900 | E33: 1153980 | F33: 267000 | G33: 0 | H33: 0 | I33: 160461 | J33: 3180 | K33: 163641 | L33: 33717 | M33: 1200 | N33: 34917 | O33: 15392
A34: 52 | B34: 5160 | C34: 15840 | D34: 51300 | E34: 46440 | F34: 9360 | G34: 720 | H34: 0 | I34: 0 | J34: 0 | K34: 0 | L34: 0 | M34: 0 | N34: 0 | O34: 0
A35: Total general | B35: 84720 | C35: 392320 | D35: 1070300 | E35: 1232460 | F35: 279360 | G35: 900 | H35: 0 | I35: 166704 | J35: 3630 | K35: 170334 | L35: 35340 | M35: 1950 | N35: 37290 | O35: 17046

Sheet Tablas
A2: SUCIO POR PACKING | B2: S01 | C2: S02 | D2: S03 | E2: S04 | F2: S05 | G2: S06 | H2: S07 | I2: S08 | J2: S09 | K2: S10 | L2: S11 | M2: S12 | N2: S13 | O2: S14 | P2: S15 | Q2: S16 | R2: S17 | S2: S18 | T2: S19 | U2: S20 | V2: S21 | W2: S22 | X2: S23 | Y2: S24 | Z2: S25 | AA2: S26 | AB2: S27 | AC2: S28 | AD2: S29 | AE2: S30 | AF2: S31 | AG2: S32 | AH2: S33 | AI2: S34 | AJ2: S35 | AK2: S36 | AL2: S37 | AM2: S38 | AN2: S39 | AO2: S40 | AP2: S41 | AQ2: S42 | AR2: S43 | AS2: S44 | AT2: S45 | AU2: S46 | AV2: S47 | AW2: S48 | AX2: S49 | AY2: S50 | AZ2: S51 | BA2: S52 | BB2: S01 | BC2: S02 | BD2: S03 | BE2: S04 | BF2: S05 | BG2: S06 | BH2: S07 | BI2: S08 | BJ2: S09 | BK2: S10 | BL2: S11 | BM2: S12 | BN2: S13 | BO2: S14 | BP2: S15 | BQ2: S16 | BR2: S17 | BS2: S18 | BT2: S19 | BU2: S20 | BV2: S21 | BW2: S22 | BX2: S23 | BY2: S24 | BZ2: S25 | CA2: S26 | CB2: S27 | CC2: S28 | CD2: S29 | CE2: S30 | CF2: S31 | CG2: S32 | CH2: S33 | CI2: S34 | CJ2: S35 | CK2: S36 | CL2: S37 | CM2: S38 | CN2: S39 | CO2: S40 | CP2: S41 | CQ2: S42 | CR2: S43 | CS2: S44 | CT2: S45 | CU2: S46 | CV2: S47 | CW2: S48 | CX2: S49 | CY2: S50 | CZ2: S51 | DA2: S52
A3: Packing 1 Color | B3: 0.055607949 | C3: 0.069243151 | D3: 0.07434488 | E3: 0.070568412 | F3: 0.072452989 | G3: 0.038179908 | H3: 0.056248781 | I3: 0.079261954 | J3: 0.077105756 | K3: 0.095750298 | L3: 0.067099275 | M3: 0.059465447 | N3: 0.088221541 | O3: 0.070874979 | P3: 0.087548241 | Q3: 0.092075797 | R3: 0.075741168 | S3: 0.067561081 | T3: 0.071031762 | U3: 0.083222752 | V3: 0.09973604 | W3: 0.10393108 | X3: 0.077080695 | Y3: 0.071832595 | Z3: 0.072505605 | AA3: 0.076901735 | AB3: 0.075664697 | AC3: 0.071672397 | AD3: 0.071547951 | AE3: 0.073264716 | AF3: 0.071851663 | AG3: 0.078977478 | AH3: 0.080686199 | AI3: 0.068731242 | AJ3: 0.077168055 | AK3: 0.061611409 | AL3: 0.065933509 | AM3: 0.054413411 | AN3: 0.06351843 | AO3: 0.067216762 | AP3: 0.056219682 | AQ3: 0.041199241 | AR3: 0.04183775 | AS3: 0.072550984 | AT3: 0.064466178 | AU3: 0.059980896 | AV3: 0.066211857 | AW3: 0.0659038 | AX3: 0.072143002 | AY3: 0.065395264 | AZ3: 0.063261377 | BA3: 0.047542078 | BB3: 0.048609736 | BC3: 0.049638419 | BD3: 0.058418343 | BE3: 0.042459493 | BF3: 0.038680611 | BG3: 0.035276324 | BH3: 0.044340584 | BI3: 0.039923653 | BJ3: 0.039613015 | BK3: 0.041749389 | BL3: 0.034883721 | BM3: 0.047859371 | BN3: 0.052641361 | BO3: 0.043387185 | BP3: 0.039486568 | BQ3: 0.023796034 | BR3: 0.03291196 | BS3: 0.040627647 | BT3: 0.032349515 | BU3: 0.036191055 | BV3: 0.041597738 | BW3: 0.044579472 | BX3: 0.0591735 | BY3: 0.043264076 | BZ3: 0.072545366 | CA3: 0.066706881 | CB3: 0.060882119 | CC3: 0.055523943 | CD3: 0.053307361 | CE3: 0.059720709 | CF3: 0.064417982 | CG3: 0.05163786 | CH3: 0.057999846 | CI3: 0.060052424 | CJ3: 0.062541822 | CK3: 0.068915983 | CL3: 0.066227517 | CM3: 0.086853786 | CN3: 0.055747325 | CO3: 0.042599319 | CP3: 0.040873352 | CQ3: 0.050798418 | CR3: 0.073144298 | CS3: 0.051468186 | CT3: 0.03178889 | CU3: 0.031122535 | CV3: 0.036870843 | CW3: 0.036676139 | CX3: 0.050196759 | CY3: 0.047596179 | CZ3: 0.046261062 | DA3: 0.047004838
A4: Packing 1 Blanco | B4: 0.079537162 | C4: 0.072246462 | D4: 0.076273194 | E4: 0.10416819 | F4: 0.081195801 | G4: 0.098784 | H4: 0.082179124 | I4: 0.094311035 | J4: 0.11431568 | K4: 0.090907935 | L4: 0.081780198 | M4: 0.066007116 | N4: 0.079655663 | O4: 0.087819602 | P4: 0.06445511 | Q4: 0.098216008 | R4: 0.080736624 | S4: 0.087309496 | T4: 0.092714088 | U4: 0.090524642 | V4: 0.07585407 | W4: 0.06066838 | X4: 0.046267015 | Y4: 0.034990107 | Z4: 0.041534593 | AA4: 0.039831164 | AB4: 0.036136244 | AC4: 0.05828224 | AD4: 0.052692497 | AE4: 0.051361844 | AF4: 0.058386357 | AG4: 0.059896573 | AH4: 0.058853359 | AI4: 0.064629582 | AJ4: 0.063250172 | AK4: 0.075363794 | AL4: 0.055556396 | AM4: 0.058432397 | AN4: 0.064157924 | AO4: 0.058055378 | AP4: 0.047587032 | AQ4: 0.077994497 | AR4: 0.069348724 | AS4: 0.068025966 | AT4: 0.059232955 | AU4: 0.092563999 | AV4: 0.071183406 | AW4: 0.083502582 | AX4: 0.10250517 | AY4: 0.072235697 | AZ4: 0.05979266 | BA4: 0.088829253 | BB4: 0.10607844 | BC4: 0.044964759 | BD4: 0.062598658 | BE4: 0.050673322 | BF4: 0.051866556 | BG4: 0.071349923 | BH4: 0.059952175 | BI4: 0.052601568 | BJ4: 0.059905728 | BK4: 0.057947686 | BL4: 0.055821984 | BM4: 0.057517084 | BN4: 0.049370403 | BO4: 0.054054054 | BP4: 0.057796183 | BQ4: 0.042132961 | BR4: 0.03784023 | BS4: 0.030255376 | BT4: 0.029553679 | BU4: 0.029447853 | BV4: 0.034812436 | BW4: 0.054703608 | BX4: 0.04258955 | BY4: 0.038135593 | BZ4: 0.04507199 | CA4: 0.059736842 | CB4: 0.053596252 | CC4: 0.045979299 | CD4: 0.053184504 | CE4: 0.047100691 | CF4: 0.055475808 | CG4: 0.061889699 | CH4: 0.072281311 | CI4: 0.088306943 | CJ4: 0.055572289 | CK4: 0.0652017 | CL4: 0.11145114 | CM4: 0.72890026 | CN4: 0.90909091 | CO4: 0.95 | CP4: 0.046833882 | CQ4: 0.045513708 | CR4: 0.046216096 | CS4: 0.037984007 | CT4: 0.04397883 | CU4: 0.04486053 | CV4: 0.038564892 | CW4: 0.064958811 | CX4: 0.057248472 | CY4: 0.05533651 | CZ4: 0.034698878 | DA4: 0.039148086
A5: Packing 3 | B5: 0.092719065 | C5: 0.098129598 | D5: 0.072033898 | E5: 0.052372583 | F5: 0.049865333 | G5: 0.045176999 | H5: 0.059648305 | I5: 0.06310858 | J5: 0.057816474 | K5: 0.068942713 | L5: 0.078750988 | M5: 0.081943952 | N5: 0.089797489 | O5: 0.088400121 | P5: 0.096561134 | Q5: 0.11851185 | R5: 0.13724541 | S5: 0.097080812 | T5: 0.10126085 | U5: 0.10162602 | V5: 0.087021755 | W5: 0.10910311 | X5: 0.086542622 | Y5: 0.09164059 | Z5: 0.10188847 | AA5: 0.11203686 | AB5: 0.092636921 | AC5: 0.10008587 | AD5: 0.10690373 | AE5: 0.076743975 | AF5: 0.066397106 | AG5: 0.081804987 | AH5: 0.10920312 | AI5: 0.093048266 | AJ5: 0.084724489 | AK5: 0.083577049 | AL5: 0.070237004 | AM5: 0.072617859 | AN5: 0.081988465 | AO5: 0.079704276 | AP5: 0.079399771 | AQ5: 0.078467931 | AR5: 0.093243243 | AS5: 0.071488158 | AT5: 0.0486668 | AU5: 0.036604525 | AV5: 0.033014968 | AW5: 0.030272661 | AX5: 0.048503861 | AY5: 0.065053116 | AZ5: 0.060002041 | BA5: 0.066268735 | BB5: 0.069930899 | BC5: 0.087089297 | BD5: 0.081515712 | BE5: 0.064712753 | BF5: 0.057690298 | BG5: 0.062429933 | BH5: 0.053261942 | BI5: 0.061716871 | BJ5: 0.061714667 | BK5: 0.065591194 | BL5: 0.066183261 | BM5: 0.070340747 | BN5: 0.072975638 | BO5: 0.06937916 | BP5: 0.069723478 | BQ5: 0.074003351 | BR5: 0.079057035 | BS5: 0.087088196 | BT5: 0.077302854 | BU5: 0.070112754 | BV5: 0.056880143 | BW5: 0.057843315 | BX5: 0.048396173 | BY5: 0.046396814 | BZ5: 0.053278082 | CA5: 0.058469475 | CB5: 0.06685437 | CC5: 0.05778192 | CD5: 0.072404939 | CE5: 0.051809034 | CF5: 0.045281753 | CG5: 0.033621411 | CH5: 0.033408128 | CI5: 0.044281675 | CJ5: 0.039209726 | CK5: 0.03842854 | CL5: 0.03966207 | CM5: 0.035097066 | CN5: 0.04294357 | CO5: 0.03952643 | CP5: 0.042309205 | CQ5: 0.041905889 | CR5: 0.039272453 | CS5: 0.042958983 | CT5: 0.037918763 | CU5: 0.047457081 | CV5: 0.050958505 | CW5: 0.050721414 | CX5: 0.049922789 | CY5: 0.053635716 | CZ5: 0.054742984 | DA5: 0.05659544
A6: Packing 4 | B6: 0.094548665 | C6: 0.080834114 | D6: 0.073164631 | E6: 0.098918408 | F6: 0.094990663 | G6: 0.09588785 | H6: 0.092033535 | I6: 0.091260415 | J6: 0.095587355 | K6: 0.091665754 | L6: 0.09274282 | M6: 0.10976889 | N6: 0.10649185 | O6: 0.09679626 | P6: 0.10873606 | Q6: 0.11825131 | R6: 0.1245618 | S6: 0.10074883 | T6: 0.10810304 | U6: 0.11859634 | V6: 0.10949948 | W6: 0.1194354 | X6: 0.12301741 | Y6: 0.14958111 | Z6: 0.1111287 | AA6: 0.10941767 | AB6: 0.10706653 | AC6: 0.13115785 | AD6: 0.13178685 | AE6: 0.13516577 | AF6: 0.11851031 | AG6: 0.12513499 | AH6: 0.14937759 | AI6: 0.1318424 | AJ6: 0.1325959 | AK6: 0.12363355 | AL6: 0.11038449 | AM6: 0.12772577 | AN6: 0.1335141 | AO6: 0.1428277 | AP6: 0.12906221 | AQ6: 0.14889464 | AR6: 0.14511912 | AS6: 0.13563295 | AT6: 0.12957631 | AU6: 0.1542888 | AV6: 0.13165714 | AW6: 0.13309138 | AX6: 0.12310948 | AY6: 0.12111064 | AZ6: 0.12742461 | BA6: 0.12001404 | BB6: 0.1548996 | BC6: 0.17962365 | BD6: 0.13990747 | BE6: 0.12228994 | BF6: 0.13173146 | BG6: 0.12119565 | BH6: 0.10452291 | BI6: 0.10955101 | BJ6: 0.11509397 | BK6: 0.12881766 | BL6: 0.092219762 | BM6: 0.10200227 | BN6: 0.09850336 | BO6: 0.11258796 | BP6: 0.1020225 | BQ6: 0.10406925 | BR6: 0.12484422 | BS6: 0.13116208 | BT6: 0.10592046 | BU6: 0.1440281 | BV6: 0.14635996 | BW6: 0.1703103 | BX6: 0.13159698 | BY6: 0.14324251 | BZ6: 0.16391784 | CA6: 0.15845983 | CB6: 0.18294461 | CC6: 0.15456059 | CD6: 0.16434783 | CE6: 0.1198282 | CF6: 0.12411139 | CG6: 0.11917278 | CH6: 0.11322535 | CI6: 0.11836787 | CJ6: 0.10946162 | CK6: 0.11770524 | CL6: 0.12641929 | CM6: 0.11910417 | CN6: 0.13000081 | CO6: 0.11695473 | CP6: 0.14379926 | CQ6: 0.15722232 | CR6: 0.1858382 | CS6: 0.070736434 | CT6: 0.074493574 | CU6: 0.099315824 | CV6: 0.087799457 | CW6: 0.085355339 | CX6: 0.071705212 | CY6: 0.064160055 | CZ6: 0.086471563 | DA6: 0.062530834
A7: Packing 5 | B7: 0.08369182 | C7: 0.061457008 | D7: 0.067036883 | E7: 0.066212344 | F7: 0.068570241 | G7: 0.065179225 | H7: 0.061139665 | I7: 0.063185203 | J7: 0.062686672 | K7: 0.069517234 | L7: 0.054019523 | M7: 0.075746596 | N7: 0.096088435 | O7: 0.097193309 | P7: 0.081071543 | Q7: 0.084399326 | R7: 0.084042537 | S7: 0.085517108 | T7: 0.084875005 | U7: 0.087030307 | V7: 0.076283728 | W7: 0.064126217 | X7: 0.068087552 | Y7: 0.058703446 | Z7: 0.062167767 | AA7: 0.068053217 | AB7: 0.068575091 | AC7: 0.082259127 | AD7: 0.097036728 | AE7: 0.081660709 | AF7: 0.090636816 | AG7: 0.12334183 | AH7: 0.13703858 | AI7: 0.14418358 | AJ7: 0.11898162 | AK7: 0.11844835 | AL7: 0.14016667 | AM7: 0.19986613 | AN7: 0.13831259 | AO7: 0.10272427 | AP7: 0.080505861 | AQ7: 0.088481114 | AR7: 0.091635916 | AS7: 0.091558323 | AT7: 0.080270115 | AU7: 0.091177138 | AV7: 0.10591222 | AW7: 0.07911145 | AX7: 0.074924393 | AY7: 0.080653664 | AZ7: 0.055256705 | BA7: 0.05580486 | BB7: 0.056461932 | BC7: 0.055811987 | BD7: 0.056479304 | BE7: 0.062301796 | BF7: 0.04466977 | BG7: 0.038710932 | BH7: 0.045126518 | BI7: 0.043497069 | BJ7: 0.055662451 | BK7: 0.042497766 | BL7: 0.045815505 | BM7: 0.043812343 | BN7: 0.048298242 | BO7: 0.046366565 | BP7: 0.047648826 | BQ7: 0.050566298 | BR7: 0.061129275 | BS7: 0.061049785 | BT7: 0.053451318 | BU7: 0.056404722 | BV7: 0.053819246 | BW7: 0.05809822 | BX7: 0.069060299 | BY7: 0.064157113 | BZ7: 0.064406431 | CA7: 0.086678212 | CB7: 0.07939378 | CC7: 0.083171329 | CD7: 0.07792256 | CE7: 0.075519538 | CF7: 0.068417393 | CG7: 0.073257006 | CH7: 0.061638118 | CI7: 0.062670332 | CJ7: 0.059006267 | CK7: 0.061989149 | CL7: 0.053479536 | CM7: 0.061884669 | CN7: 0.068458104 | CO7: 0.065088205 | CP7: 0.055837964 | CQ7: 0.082442194 | CR7: 0.053916004 | CS7: 0.048660617 | CT7: 0.06967185 | CU7: 0.072212389 | CV7: 0.062304593 | CW7: 0.054631431 | CX7: 0.044936503 | CY7: 0.045394295 | CZ7: 0.045933888 | DA7: 0.056337001
A9: TRIZADO POR PACKING | B9: S01 | C9: S02 | D9: S03 | E9: S04 | F9: S05 | G9: S06 | H9: S07 | I9: S08 | J9: S09 | K9: S10 | L9: S11 | M9: S12 | N9: S13 | O9: S14 | P9: S15 | Q9: S16 | R9: S17 | S9: S18 | T9: S19 | U9: S20 | V9: S21 | W9: S22 | X9: S23 | Y9: S24 | Z9: S25 | AA9: S26 | AB9: S27 | AC9: S28 | AD9: S29 | AE9: S30 | AF9: S31 | AG9: S32 | AH9: S33 | AI9: S34 | AJ9: S35 | AK9: S36 | AL9: S37 | AM9: S38 | AN9: S39 | AO9: S40 | AP9: S41 | AQ9: S42 | AR9: S43 | AS9: S44 | AT9: S45 | AU9: S46 | AV9: S47 | AW9: S48 | AX9: S49 | AY9: S50 | AZ9: S51 | BA9: S52 | BB9: S01 | BC9: S02 | BD9: S03 | BE9: S04 | BF9: S05 | BG9: S06 | BH9: S07 | BI9: S08 | BJ9: S09 | BK9: S10 | BL9: S11 | BM9: S12 | BN9: S13 | BO9: S14 | BP9: S15 | BQ9: S16 | BR9: S17 | BS9: S18 | BT9: S19 | BU9: S20 | BV9: S21 | BW9: S22 | BX9: S23 | BY9: S24 | BZ9: S25 | CA9: =+CA2 -> S26 | CB9: =+CB2 -> S27 | CC9: =+CC2 -> S28 | CD9: =+CD2 -> S29 | CE9: =+CE2 -> S30 | CF9: =+CF2 -> S31 | CG9: =+CG2 -> S32 | CH9: =+CH2 -> S33 | ... DA9: =+DA2 -> S52
A10: Packing 1 Color | B10: 0.026751431 | C10: 0.036890111 | D10: 0.031931476 | E10: 0.03014784 | F10: 0.026352024 | G10: 0.013635681 | H10: 0.015673971 | I10: 0.027806653 | J10: 0.024964904 | K10: 0.037486412 | L10: 0.024498567 | M10: 0.021660224 | N10: 0.023895518 | O10: 0.019402195 | P10: 0.01946084 | Q10: 0.023263644 | R10: 0.01767008 | S10: 0.017084128 | T10: 0.015890708 | U10: 0.021211235 | V10: 0.021640195 | W10: 0.018933709 | X10: 0.023089674 | Y10: 0.021521225 | Z10: 0.019569787 | AA10: 0.015671395 | AB10: 0.018471207 | AC10: 0.020090366 | AD10: 0.01995907 | AE10: 0.019330142 | AF10: 0.020775546 | AG10: 0.021808483 | AH10: 0.019892059 | AI10: 0.018081651 | AJ10: 0.020725135 | AK10: 0.017209439 | AL10: 0.014790314 | AM10: 0.020553744 | AN10: 0.019548356 | AO10: 0.022302121 | AP10: 0.020808475 | AQ10: 0.021511522 | AR10: 0.023231889 | AS10: 0.029400216 | AT10: 0.024630341 | AU10: 0.024883441 | AV10: 0.024816601 | AW10: 0.028318468 | AX10: 0.02633642 | AY10: 0.023188975 | AZ10: 0.029760778 | BA10: 0.01903061 | BB10: 0.023010373 | BC10: 0.018400852 | BD10: 0.020784115 | BE10: 0.016673748 | BF10: 0.020095508 | BG10: 0.022424787 | BH10: 0.025452091 | BI10: 0.020944973 | BJ10: 0.0235464 | BK10: 0.018362881 | BL10: 0.020912297 | BM10: 0.020820338 | BN10: 0.022667875 | BO10: 0.018129645 | BP10: 0.014221585 | BQ10: 0.013356107 | BR10: 0.013028451 | BS10: 0.014693878 | BT10: 0.01318835 | BU10: 0.014116486 | BV10: 0.010421993 | BW10: 0.015663058 | BX10: 0.014183552 | BY10: 0.015938084 | BZ10: 0.018806352 | CA10: 0.01390467 | CB10: 0.015427001 | CC10: 0.014061822 | CD10: 0.013801393 | CE10: 0.017143706 | CF10: 0.018788214 | CG10: 0.015572226 | CH10: 0.014270308 | CI10: 0.020291645 | CJ10: 0.020052955 | CK10: 0.018179623 | CL10: 0.019674976 | CM10: 0.015039164 | CN10: 0.017362789 | CO10: 0.018217934 | CP10: 0.024647344 | CQ10: 0.028783635 | CR10: 0.024456411 | CS10: 0.027136255 | CT10: 0.016432825 | CU10: 0.015691893 | CV10: 0.027794599 | CW10: 0.021821189 | CX10: 0.026896391 | CY10: 0.024111862 | CZ10: 0.021743363 | DA10: 0.018883207
A11: Packing 1 Blanco | B11: 0.022210486 | C11: 0.022890284 | D11: 0.025552704 | E11: 0.02572054 | F11: 0.023311273 | G11: 0.031296 | H11: 0.024870984 | I11: 0.022241281 | J11: 0.034609334 | K11: 0.025178026 | L11: 0.027234743 | M11: 0.017077586 | N11: 0.025635761 | O11: 0.028018466 | P11: 0.02377188 | Q11: 0.057280617 | R11: 0.024585531 | S11: 0.030026377 | T11: 0.033408149 | U11: 0.06572337 | V11: 0.047764656 | W11: 0.011413882 | X11: 0.012072047 | Y11: 0.0098219232 | Z11: 0.014955597 | AA11: 0.011767696 | AB11: 0.0089250357 | AC11: 0.013685961 | AD11: 0.011294798 | AE11: 0.0087894495 | AF11: 0.013631525 | AG11: 0.010393429 | AH11: 0.013522065 | AI11: 0.018956678 | AJ11: 0.013783027 | AK11: 0.041589498 | AL11: 0.015367749 | AM11: 0.01389288 | AN11: 0.01184572 | AO11: 0.01095109 | AP11: 0.0080850094 | AQ11: 0.0072179762 | AR11: 0.010452784 | AS11: 0.0098615379 | AT11: 0.0094899892 | AU11: 0.013689873 | AV11: 0.010399964 | AW11: 0.0168544 | AX11: 0.020880682 | AY11: 0.013011842 | AZ11: 0.014365732 | BA11: 0.019385543 | BB11: 0.023913555 | BC11: 0.013779716 | BD11: 0.014206788 | BE11: 0.012015324 | BF11: 0.010661459 | BG11: 0.015194891 | BH11: 0.01178547 | BI11: 0.012188168 | BJ11: 0.012855306 | BK11: 0.012072435 | BL11: 0.012852484 | BM11: 0.01309795 | BN11: 0.014025683 | BO11: 0.011261261 | BP11: 0.011883327 | BQ11: 0.014836889 | BR11: 0.018588183 | BS11: 0.010050938 | BT11: 0.0096501809 | BU11: 0.011042945 | BV11: 0.011166253 | BW11: 0.011984536 | BX11: 0.013604995 | BY11: 0.012916894 | BZ11: 0.016901996 | CA11: 0.02 | CB11: 0.018843639 | CC11: 0.014729299 | CD11: 0.024950755 | CE11: 0.030144442 | CF11: 0.02051845 | CG11: 0.032182643 | CH11: 0.026047319 | CI11: 0.03410475 | CJ11: 0.031174699 | CK11: 0.037533082 | CL11: 0.083695111 | CM11: 0.2455243 | CN11: 0.090909091 | CO11: 0.05 | CP11: 0.019675164 | CQ11: 0.018457491 | CR11: 0.013602099 | CS11: 0.014204545 | CT11: 0.013118168 | CU11: 0.021279995 | CV11: 0.020262909 | CW11: 0.011779198 | CX11: 0.018267132 | CY11: 0.019275208 | CZ11: 0.026237821 | DA11: 0.022164583
A12: Packing 3 | B12: 0.017710383 | C12: 0.017817569 | D12: 0.041525424 | E12: 0.015817223 | F12: 0.017660639 | G12: 0.013485671 | H12: 0.01318857 | I12: 0.013779166 | J12: 0.014674232 | K12: 0.011159792 | L12: 0.010271868 | M12: 0.010908123 | N12: 0.012523685 | O12: 0.014642965 | P12: 0.013953921 | Q12: 0.01470147 | R12: 0.015871918 | S12: 0.01505874 | T12: 0.016394614 | U12: 0.017615176 | V12: 0.015378845 | W12: 0.012883024 | X12: 0.010385115 | Y12: 0.0093875726 | Z12: 0.0084536286 | AA12: 0.0097039796 | AB12: 0.011777097 | AC12: 0.011206526 | AD12: 0.010894647 | AE12: 0.0097971032 | AF12: 0.062566504 | AG12: 0.011083256 | AH12: 0.009446637 | AI12: 0.011227738 | AJ12: 0.011861428 | AK12: 0.0092260379 | AL12: 0.0082493126 | AM12: 0.0089861565 | AN12: 0.0078575586 | AO12: 0.0086992868 | AP12: 0.0079159892 | AQ12: 0.0081504368 | AR12: 0.0083563155 | AS12: 0.006093359 | AT12: 0.0069165998 | AU12: 0.0056556347 | AV12: 0.0078688525 | AW12: 0.01658776 | AX12: 0.011100386 | AY12: 0.0085423283 | AZ12: 0.0076533215 | BA12: 0.0090188219 | BB12: 0.0085411786 | BC12: 0.01158983 | BD12: 0.010314233 | BE12: 0.01149719 | BF12: 0.0087789584 | BG12: 0.010089686 | BH12: 0.011096238 | BI12: 0.012601874 | BJ12: 0.011675748 | BK12: 0.011615107 | BL12: 0.010774019 | BM12: 0.011175633 | BN12: 0.011176449 | BO12: 0.013875832 | BP12: 0.011676181 | BQ12: 0.0098203499 | BR12: 0.0099280928 | BS12: 0.010969124 | BT12: 0.013086704 | BU12: 0.01027969 | BV12: 0.0084762566 | BW12: 0.013527872 | BX12: 0.006406523 | BY12: 0.0044187442 | BZ12: 0.0063933698 | CA12: 0.0079296838 | CB12: 0.0080872222 | CC12: 0.006100144 | CD12: 0.0063821983 | CE12: 0.03682295 | CF12: 0.0035219141 | CG12: 0.0047672149 | CH12: 0.0037397158 | CI12: 0.006077877 | CJ12: 0.0058358663 | CK12: 0.0050280333 | CL12: 0.005300461 | CM12: 0.0055618301 | CN12: 0.0059958947 | CO12: 0.005128709 | CP12: 0.004779701 | CQ12: 0.0040840485 | CR12: 0.0035873875 | CS12: 0.004463271 | CT12: 0.0042336483 | CU12: 0.0048906153 | CV12: 0.0049138559 | CW12: 0.0051484142 | CX12: 0.0062174902 | CY12: 0.0054917116 | CZ12: 0.0061563223 | DA12: 0.0054891899
A13: Packing 4 | B13: 0.021452218 | C13: 0.024835989 | D13: 0.018384959 | E13: 0.019846687 | F13: 0.017902087 | G13: 0.01682243 | H13: 0.013195985 | I13: 0.01084914 | J13: 0.012209587 | K13: 0.019713065 | L13: 0.01940364 | M13: 0.016779957 | N13: 0.015649984 | O13: 0.016075704 | P13: 0.019168216 | Q13: 0.016125179 | R13: 0.018438425 | S13: 0.017192634 | T13: 0.015624267 | U13: 0.024044189 | V13: 0.028446484 | W13: 0.023525154 | X13: 0.023597679 | Y13: 0.039756283 | Z13: 0.009260725 | AA13: 0.011100344 | AB13: 0.012822339 | AC13: 0.016459024 | AD13: 0.021738037 | AE13: 0.018702182 | AF13: 0.018754157 | AG13: 0.021463283 | AH13: 0.023192837 | AI13: 0.022731447 | AJ13: 0.020757825 | AK13: 0.024813776 | AL13: 0.025406718 | AM13: 0.029945312 | AN13: 0.028286472 | AO13: 0.029214757 | AP13: 0.031104921 | AQ13: 0.032941291 | AR13: 0.033120279 | AS13: 0.032652378 | AT13: 0.037021802 | AU13: 0.037223521 | AV13: 0.040114286 | AW13: 0.035588538 | AX13: 0.029267537 | AY13: 0.11234245 | AZ13: 0.050261928 | BA13: 0.024213358 | BB13: 0.020819839 | BC13: 0.21383767 | BD13: 0.040925314 | BE13: 0.03686682 | BF13: 0.033377046 | BG13: 0.025181159 | BH13: 0.023285673 | BI13: 0.023063371 | BJ13: 0.022670025 | BK13: 0.024493499 | BL13: 0.025487874 | BM13: 0.033029305 | BN13: 0.030238241 | BO13: 0.036942924 | BP13: 0.033685373 | BQ13: 0.032415013 | BR13: 0.038038472 | BS13: 0.038588265 | BT13: 0.035741187 | BU13: 0.034125125 | BV13: 0.056875632 | BW13: 0.017983075 | BX13: 0.015421522 | BY13: 0.015780955 | BZ13: 0.01365982 | CA13: 0.025546094 | CB13: 0.0196793 | CC13: 0.033120126 | CD13: 0.02673913 | CE13: 0.024137437 | CF13: 0.025175049 | CG13: 0.020085301 | CH13: 0.022173298 | CI13: 0.021748893 | CJ13: 0.019429638 | CK13: 0.023244313 | CL13: 0.018962894 | CM13: 0.015778758 | CN13: 0.018015094 | CO13: 0.019153876 | CP13: 0.02460994 | CQ13: 0.030505823 | CR13: 0.027154441 | CS13: 0.021317829 | CT13: 0.021563929 | CU13: 0.02284264 | CV13: 0.020004939 | CW13: 0.014410642 | CX13: 0.02091402 | CY13: 0.023801311 | CZ13: 0.021866372 | DA13: 0.022200296
A14: Packing 5 | B14: 0.029255749 | C14: 0.014311906 | D14: 0.013816762 | E14: 0.01271974 | F14: 0.015584146 | G14: 0.017776152 | H14: 0.015284916 | I14: 0.013850619 | J14: 0.013908875 | K14: 0.014797924 | L14: 0.010867566 | M14: 0.010984401 | N14: 0.012843068 | O14: 0.012379182 | P14: 0.011797724 | Q14: 0.012427733 | R14: 0.012508003 | S14: 0.01317504 | T14: 0.01403752 | U14: 0.01671443 | V14: 0.017086479 | W14: 0.014170749 | X14: 0.0164976 | Y14: 0.014489146 | Z14: 0.015114785 | AA14: 0.017126979 | AB14: 0.013939329 | AC14: 0.014444764 | AD14: 0.014398998 | AE14: 0.018868573 | AF14: 0.016846992 | AG14: 0.021347624 | AH14: 0.022720496 | AI14: 0.021225964 | AJ14: 0.022069171 | AK14: 0.021501771 | AL14: 0.024691613 | AM14: 0.047485924 | AN14: 0.033886584 | AO14: 0.031199922 | AP14: 0.025293029 | AQ14: 0.01880525 | AR14: 0.025830258 | AS14: 0.018861014 | AT14: 0.021596483 | AU14: 0.020072579 | AV14: 0.021218716 | AW14: 0.018533702 | AX14: 0.020633475 | AY14: 0.018236031 | AZ14: 0.01060655 | BA14: 0.01005493 | BB14: 0.01087652 | BC14: 0.013001656 | BD14: 0.012940002 | BE14: 0.010764185 | BF14: 0.010107652 | BG14: 0.014203272 | BH14: 0.015404162 | BI14: 0.017187936 | BJ14: 0.013693552 | BK14: 0.011056201 | BL14: 0.012815752 | BM14: 0.012940034 | BN14: 0.015122072 | BO14: 0.014099352 | BP14: 0.01183754 | BQ14: 0.011082178 | BR14: 0.012819961 | BS14: 0.012494503 | BT14: 0.012483133 | BU14: 0.011182672 | BV14: 0.013485429 | BW14: 0.015475345 | BX14: 0.014307777 | BY14: 0.013372498 | BZ14: 0.014458946 | CA14: 0.014039161 | CB14: 0.015346582 | CC14: 0.013971885 | CD14: 0.012820849 | CE14: 0.011785374 | CF14: 0.012906083 | CG14: 0.014917977 | CH14: 0.012756632 | CI14: 0.010891207 | CJ14: 0.0092654469 | CK14: 0.010305101 | CL14: 0.010430308 | CM14: 0.011603376 | CN14: 0.010817308 | CO14: 0.010595754 | CP14: 0.008951124 | CQ14: 0.015979985 | CR14: 0.01139288 | CS14: 0.008580732 | CT14: 0.010019182 | CU14: 0.010081384 | CV14: 0.0083839583 | CW14: 0.0075457777 | CX14: 0.010047914 | CY14: 0.010070407 | CZ14: 0.0094301359 | DA14: 0.010768378
A16: LIQUIDO POR PACKING | B16: S01 | C16: S02 | D16: S03 | E16: S04 | F16: S05 | G16: S06 | H16: S07 | I16: S08 | J16: S09 | K16: S10 | L16: S11 | M16: S12 | N16: S13 | O16: S14 | P16: S15 | Q16: S16 | R16: S17 | S16: S18 | T16: S19 | U16: S20 | V16: S21 | W16: S22 | X16: S23 | Y16: S24 | Z16: S25 | AA16: S26 | AB16: S27 | AC16: S28 | AD16: S29 | AE16: S30 | AF16: S31 | AG16: S32 | AH16: S33 | AI16: S34 | AJ16: S35 | AK16: S36 | AL16: S37 | AM16: S38 | AN16: S39 | AO16: S40 | AP16: S41 | AQ16: S42 | AR16: S43 | AS16: S44 | AT16: S45 | AU16: S46 | AV16: S47 | AW16: S48 | AX16: S49 | AY16: S50 | AZ16: S51 | BA16: S52 | BB16: S01 | BC16: S02 | BD16: S03 | BE16: S04 | BF16: S05 | BG16: S06 | BH16: S07 | BI16: S08 | BJ16: S09 | BK16: S10 | BL16: S11 | BM16: S12 | BN16: S13 | BO16: S14 | BP16: S15 | BQ16: S16 | BR16: S17 | BS16: S18 | BT16: S19 | BU16: S20 | BV16: S21 | BW16: S22 | BX16: S23 | BY16: S24 | BZ16: S25 | CA16: =+CA9 -> S26 | CB16: =+CB9 -> S27 | CC16: =+CC9 -> S28 | CD16: =+CD9 -> S29 | CE16: =+CE9 -> S30 | CF16: =+CF9 -> S31 | CG16: =+CG9 -> S32 | CH16: =+CH9 -> S33 | ... DA16: =+DA9 -> S52
A17: Packing 1 Color | B17: 0.011387111 | C17: 0.010931894 | D17: 0.012548946 | E17: 0.0079899024 | F17: 0.0064121247 | G17: 0.0033887656 | H17: 0.0079263931 | I17: 0.009009009 | J17: 0.011718141 | K17: 0.0079610746 | L17: 0.0096438002 | M17: 0.0072436441 | N17: 0.0086235623 | O17: 0.0075745839 | P17: 0.0073685206 | Q17: 0.0061597891 | R17: 0.0063403563 | S17: 0.0050218475 | T17: 0.0081061353 | U17: 0.0098208283 | V17: 0.010467392 | W17: 0.0046503847 | X17: 0.0059422125 | Y17: 0.01147853 | Z17: 0.0078405269 | AA17: 0.0073460238 | AB17: 0.0074383423 | AC17: 0.0098289909 | AD17: 0.0074829932 | AE17: 0.008875203 | AF17: 0.0094183404 | AG17: 0.0097278771 | AH17: 0.0089565664 | AI17: 0.0075011306 | AJ17: 0.010570799 | AK17: 0.011330834 | AL17: 0.0051546392 | AM17: 0.0032772128 | AN17: 0.0095957169 | AO17: 0.0078427315 | AP17: 0.0057987176 | AQ17: 0.012553584 | AR17: 0.016462422 | AS17: 0.015321127 | AT17: 0.007092405 | AU17: 0.0083604358 | AV17: 0.0096480461 | AW17: 0.015002746 | AX17: 0.013705481 | AY17: 0.0091264102 | AZ17: 0.010577753 | BA17: 0.017569706 | BB17: 0.012053975 | BC17: 0.011781616 | BD17: 0.015851402 | BE17: 0.016958917 | BF17: 0.014215951 | BG17: 0.014895356 | BH17: 0.015531557 | BI17: 0.015934409 | BJ17: 0.021906687 | BK17: 0.017493895 | BL17: 0.026884677 | BM17: 0.026774407 | BN17: 0.014637773 | BO17: 0.018324773 | BP17: 0.0090744199 | BQ17: 0.038668555 | BR17: 0.011569111 | BS17: 0.014666923 | BT17: 0.012196764 | BU17: 0.013098944 | BV17: 0.016497729 | BW17: 0.013345492 | BX17: 0.012693683 | BY17: 0.008281737 | BZ17: 0.016374973 | CA17: 0.017986795 | CB17: 0.013462112 | CC17: 0.015807494 | CD17: 0.016279841 | CE17: 0.013583243 | CF17: 0.013923019 | CG17: 0.014146096 | CH17: 0.012773948 | CI17: 0.014651562 | CJ17: 0.022351667 | CK17: 0.01146789 | CL17: 0.012340907 | CM17: 0.010639687 | CN17: 0.016154643 | CO17: 0.017758229 | CP17: 0.013592333 | CQ17: 0.0079396996 | CR17: 0.018205985 | CS17: 0.011328492 | CT17: 0.012937434 | CU17: 0.0086830721 | CV17: 0.015747543 | CW17: 0.01311604 | CX17: 0.01245793 | CY17: 0.015376321 | CZ17: 0.011818584 | DA17: 0.010048376
A18: Packing 1 Blanco | B18: 0.015018245 | C18: 0.0092582739 | D18: 0.015821161 | E18: 0.012942357 | F18: 0.016898676 | G18: 0.01488 | H18: 0.020467788 | I18: 0.021812464 | J18: 0.022548506 | K18: 0.030150051 | L18: 0.030260826 | M18: 0.017345983 | N18: 0.037024167 | O18: 0.023366477 | P18: 0.01905703 | Q18: 0.037367406 | R18: 0.029380181 | S18: 0.03330891 | T18: 0.050328039 | U18: 0.07872814 | V18: 0.031168283 | W18: 0.0076092545 | X18: 0.007520968 | Y18: 0.0032555072 | Z18: 0.0045215204 | AA18: 0.0045987934 | AB18: 0.0054913657 | AC18: 0.0094513146 | AD18: 0.0096110674 | AE18: 0.0090315996 | AF18: 0.011124252 | AG18: 0.0094436558 | AH18: 0.0091383429 | AI18: 0.0089797488 | AJ18: 0.0087147628 | AK18: 0.012282487 | AL18: 0.015063418 | AM18: 0.0038994121 | AN18: 0.0044366253 | AO18: 0.0075489514 | AP18: 0.0052646573 | AQ18: 0.0065943137 | AR18: 0.0067086936 | AS18: 0.0043955665 | AT18: 0.0054788961 | AU18: 0.0064286019 | AV18: 0.0032198031 | AW18: 0.0068069178 | AX18: 0.0081568526 | AY18: 0.0068721168 | AZ18: 0.0086638692 | BA18: 0.0055946275 | BB18: 0.0078205189 | BC18: 0.0026181659 | BD18: 0.0021211523 | BE18: 0.0018574414 | BF18: 0.0017609016 | BG18: 0 | BH18: 0.0011956274 | BI18: 0.0005702067 | BJ18: 0.00057134695 | BK18: 0.00060362173 | BL18: 0.00038365624 | BM18: 0 | BN18: 0.00043635457 | BO18: 0.00025025025 | BP18: 0.00078021846 | BQ18: 0 | BR18: 0 | BS18: 0.0031451916 | BT18: 0.0018764241 | BU18: 0.0016359918 | BV18: 0.0018245512 | BW18: 0.0006443299 | BX18: 0.0019060138 | BY18: 0.0031437944 | BZ18: 0.0011128886 | CA18: 0.0044736842 | CB18: 0.0031406065 | CC18: 0.00079617834 | CD18: 0.0017509302 | CE18: 0.0027213732 | CF18: 0.00075994258 | CG18: 0.001856691 | CH18: 0.00086824398 | CI18: 0.0016240357 | CJ18: 0.0021837349 | CK18: 0.002245569 | CL18: 0.0063340687 | CM18: 0.025575448 | CN18: 0 | CO18: 0 | CP18: 0.005859375 | CQ18: 0.0074771531 | CR18: 0.004330796 | CS18: 0.0054713805 | CT18: 0.005196946 | CU18: 0.003418858 | CV18: 0.0029777035 | CW18: 0.003483717 | CX18: 0.0055625273 | CY18: 0.0042102376 | CZ18: 0.0057831463 | DA18: 0.0060929243
A19: Packing 3 | B19: 0.003790948 | C19: 0.0038117188 | D19: 0.0034839925 | E19: 0.0024604569 | F19: 0.0022316275 | G19: 0.0023974527 | H19: 0.0025644441 | I19: 0.0029395554 | J19: 0.00273919 | K19: 0.0033066049 | L19: 0.0034532206 | M19: 0.0035473572 | N19: 0.002990289 | O19: 0.0034648991 | P19: 0.0037520543 | Q19: 0.00380038 | R19: 0.0042186798 | S19: 0.0040583838 | T19: 0.0034646569 | U19: 0.0040274014 | V19: 0.0036259065 | W19: 0.0034444196 | X19: 0.0025962787 | Y19: 0.002135797 | Z19: 0.0028673126 | AA19: 0.0029896099 | AB19: 0.0033512064 | AC19: 0.0027908974 | AD19: 0.0031019482 | AE19: 0.0026004657 | AF19: 0.0027665461 | AG19: 0.0023749835 | AH19: 0.0021832228 | AI19: 0.0020648714 | AJ19: 0.0019455253 | AK19: 0.0018693279 | AL19: 0.0020688752 | AM19: 0.0018889818 | AN19: 0.0018254934 | AO19: 0.0018548029 | AP19: 0.0020256403 | AQ19: 0.0023705519 | AR19: 0.0022890237 | AS19: 0.00094301984 | AT19: 0.0016372628 | AU19: 0.0017281106 | AV19: 0.00037063435 | AW19: 0.00095034039 | AX19: 0.00072393822 | AY19: 0.00065710218 | AZ19: 0.00068029525 | BA19: 0.00082781457 | BB19: 0.00097867671 | BC19: 0.0026181659 | BD19: 0.0012939002 | BE19: 0.0012774655 | BF19: 0.001288974 | BG19: 0.0011210762 | BH19: 0.0013385938 | BI19: 0.0005702067 | BJ19: 0.0015567664 | BK19: 0.0015562725 | BL19: 0.0011971132 | BM19: 0.0018626055 | BN19: 0.0017896928 | BO19: 0.0016169669 | BP19: 0.0017421603 | BQ19: 0.0017146643 | BR19: 0.0017976794 | BS19: 0.0018097208 | BT19: 0.0016569728 | BU19: 0.0018157856 | BV19: 0.0015118469 | BW19: 0.0016585897 | BX19: 0.0009706853 | BY19: 0.0010364956 | BZ19: 0.0011247595 | CA19: 0.00098722971 | CB19: 0.0012280597 | CC19: 0.0010166907 | CD19: 0.0011492848 | CE19: 0.0011417969 | CF19: 0.0010342129 | CG19: 0.00080847505 | CH19: 0.0011357655 | CI19: 0.000623372 | CJ19: 0.0013779129 | CK19: 0.0021349189 | CL19: 0.0037164152 | CM19: 0.0049225393 | CN19: 0.0049155533 | CO19: 0.0036844174 | CP19: 0.0035208497 | CQ19: 0.0038078327 | CR19: 0.0034615143 | CS19: 0.0047318938 | CT19: 0.0053585307 | CU19: 0.0043874655 | CV19: 0.0051160722 | CW19: 0.0047458633 | CX19: 0.0043481795 | CY19: 0.0043730296 | CZ19: 0.0056131174 | DA19: 0.0044165896
A20: Packing 4 | B20: 0.0035312293 | C20: 0.0036316776 | D20: 0.0037103431 | E20: 0.0031502678 | F20: 0.0038158643 | G20: 0.0036635514 | H20: 0.0024061055 | I20: 0.00241092 | J20: 0.0025355025 | K20: 0.0033950279 | L20: 0.0035080026 | M20: 0.0040396193 | N20: 0.0037975696 | O20: 0.0037623988 | P20: 0.0044144981 | Q20: 0.0048972766 | R20: 0.0055542909 | S20: 0.004431879 | T20: 0.0060995636 | U20: 0.0059568938 | V20: 0.0063214409 | W20: 0.0062733744 | X20: 0.0054158607 | Y20: 0.004112719 | Z20: 0.0017413329 | AA20: 0.0017619593 | AB20: 0.0022082918 | AC20: 0.0032003658 | AD20: 0.0030694913 | AE20: 0.0027392085 | AF20: 0.0041232543 | AG20: 0.0036447084 | AH20: 0.0046735095 | AI20: 0.0049136664 | AJ20: 0.005601318 | AK20: 0.0062880913 | AL20: 0.0067778745 | AM20: 0.0078213529 | AN20: 0.0089470254 | AO20: 0.0082440231 | AP20: 0.0082017951 | AQ20: 0.0076619003 | AR20: 0.0078442766 | AS20: 0.0090421969 | AT20: 0.007992008 | AU20: 0.0080920698 | AV20: 0.0076 | AW20: 0.0088835924 | AX20: 0.0081556806 | AY20: 0.0082810692 | AZ20: 0.0070791448 | BA20: 0.005497719 | BB20: 0.005089294 | BC20: 0.0042767535 | BD20: 0.0045736946 | BE20: 0.0060945149 | BF20: 0.006430052 | BG20: 0.0023550725 | BH20: 0.0046688065 | BI20: 0.0036837328 | BJ20: 0.0042142996 | BK20: 0.0052414071 | BL20: 0.0063333505 | BM20: 0.0055588537 | BN20: 0.0070250458 | BO20: 0.0080140735 | BP20: 0.0075930144 | BQ20: 0.0065082775 | BR20: 0.0066106746 | BS20: 0.0079204157 | BT20: 0.007128151 | BU20: 0.0073603212 | BV20: 0.0053926525 | BW20: 0.0032910202 | BX20: 0.0037697053 | BY20: 0.006204478 | BZ20: 0.0061722149 | CA20: 0.0043193879 | CB20: 0.0019436346 | CC20: 0.0074476474 | CD20: 0.0064492754 | CE20: 0.0057265569 | CF20: 0.0059864236 | CG20: 0.0058520135 | CH20: 0.0064475546 | CI20: 0.0068646949 | CJ20: 0.0071428571 | CK20: 0.0075832509 | CL20: 0.01147138 | CM20: 0.0088225314 | CN20: 0.0073845654 | CO20: 0.0077711853 | CP20: 0.0070773685 | CQ20: 0.0089518512 | CR20: 0.011408637 | CS20: 0.003875969 | CT20: 0.0054454367 | CU20: 0.0058485985 | CV20: 0.0060508768 | CW20: 0.0049267151 | CX20: 0.0064180591 | CY20: 0.0072438772 | CZ20: 0.0080618443 | DA20: 0.0094967933
A21: Packing 5 | B21: 0.0047223211 | C21: 0.0042842176 | D21: 0.0047951177 | E21: 0.0046077596 | F21: 0.004900348 | G21: 0.0050658376 | H21: 0.0044692737 | I21: 0.0045142757 | J21: 0.0049105686 | K21: 0.0044774239 | L21: 0.0041945923 | M21: 0.003680537 | N21: 0.0036945813 | O21: 0.0036988848 | P21: 0.0035964573 | Q21: 0.004006009 | R21: 0.0035759459 | S21: 0.0035712562 | T21: 0.0037693341 | U21: 0.0037143177 | V21: 0.0038268929 | W21: 0.0038011324 | X21: 0.0037127367 | Y21: 0.0034853615 | Z21: 0.0035194813 | AA21: 0.00067362748 | AB21: 0.0038453322 | AC21: 0.0043756652 | AD21: 0.0040692821 | AE21: 0.0041930162 | AF21: 0.0043427801 | AG21: 0.0046209259 | AH21: 0.0042340032 | AI21: 0.00441942 | AJ21: 0.0045844172 | AK21: 0.0046943437 | AL21: 0.0044762573 | AM21: 0.0074024491 | AN21: 0.0063393269 | AO21: 0.008372306 | AP21: 0.006991569 | AQ21: 0.0048486472 | AR21: 0.0035533689 | AS21: 0.0035402551 | AT21: 0.0033764414 | AU21: 0.003402132 | AV21: 0.0036271309 | AW21: 0.0054723997 | AX21: 0.0059835453 | AY21: 0.0031464154 | AZ21: 0.0036115494 | BA21: 0.0027185551 | BB21: 0.0027191299 | BC21: 0.0022021775 | BD21: 0.002858641 | BE21: 0.0028450791 | BF21: 0.0030928135 | BG21: 0.0042397688 | BH21: 0.0032365056 | BI21: 0.0030185948 | BJ21: 0.0034984567 | BK21: 0.0036131118 | BL21: 0.0042299549 | BM21: 0.0040132087 | BN21: 0.0031420009 | BO21: 0.0033842299 | BP21: 0.0039905572 | BQ21: 0.0036701453 | BR21: 0.0045192515 | BS21: 0.005046618 | BT21: 0.0059658501 | BU21: 0.0057561646 | BV21: 0.0064509008 | BW21: 0.005169726 | BX21: 0.005193007 | BY21: 0.0045422156 | BZ21: 0.0041307078 | CA21: 0.0043057308 | CB21: 0.0052930779 | CC21: 0.0047243849 | CD21: 0.0051182993 | CE21: 0.0050685206 | CF21: 0.0067959886 | CG21: 0.0045893956 | CH21: 0.0050221075 | CI21: 0.0029189347 | CJ21: 0.0024202142 | CK21: 0.0023076381 | CL21: 0.0052750982 | CM21: 0.0055672761 | CN21: 0.0052712912 | CO21: 0.0052885334 | CP21: 0.0044834554 | CQ21: 0.0053064848 | CR21: 0.0053277061 | CS21: 0.0041140972 | CT21: 0.0044529698 | CU21: 0.0047163401 | CV21: 0.0038667562 | CW21: 0.0041417935 | CX21: 0.0044037152 | CY21: 0.0041314489 | CZ21: 0.0039376732 | DA21: 0.004216885
A25: SUCIO POR SECTOR | B25: =+B2 -> S01 | C25: =+C2 -> S02 | D25: =+D2 -> S03 | E25: =+E2 -> S04 | F25: =+F2 -> S05 | G25: =+G2 -> S06 | H25: =+H2 -> S07 | I25: =+I2 -> S08 | ... BA25: =+BA2 -> S52 | BB25: 1 | BC25: 2 | BD25: 3 | BE25: 4 | BF25: 5 | BG25: 6 | BH25: 7 | BI25: 8 | BJ25: 9 | BK25: 10 | BL25: 11 | BM25: 12 | BN25: 13 | BO25: 14 | BP25: 15 | BQ25: 16 | BR25: 17 | BS25: 18 | BT25: 19 | BU25: 20 | BV25: 21 | BW25: 22 | BX25: 23 | BY25: 24 | BZ25: 25 | CA25: 26 | CB25: 27 | CC25: 28 | CD25: 29 | CE25: 30 | CF25: 31 | CG25: 32 | CH25: 33 | CI25: 34 | CJ25: 35 | CK25: 36 | CL25: 37 | CM25: 38 | CN25: 39 | CO25: 40 | CP25: 41 | CQ25: 42 | CR25: 43 | CS25: 44 | CT25: 45 | CU25: 46 | CV25: 47 | CW25: 48 | CX25: 49 | CY25: 50 | CZ25: 51 | DA25: 52
A26: CA3A | B26: 0.033376912 | C26: 0.038995502 | D26: 0.03782235 | E26: 0 | F26: 0 | G26: 0 | H26: 0 | I26: 0 | J26: 0.02826087 | K26: 0.17391304 | L26: 0.029948586 | M26: 0.019383533 | N26: 0.030925804 | O26: 0.042051894 | P26: 0.019213483 | Q26: 0.034364588 | R26: 0.020109864 | S26: 0.029520295 | T26: 0.031945271 | U26: 0.030650051 | V26: 0.053846154 | W26: 0.036385973 | X26: 0.01845805 | Y26: 0.01845805 | Z26: 0.019022783 | AA26: 0.020320448 | AB26: 0.022906091 | AC26: 0.019221509 | AD26: 0.016375345 | AE26: 0.031114612 | AF26: 0.016680887 | AG26: 0.034232026 | AH26: 0.019452736 | AI26: 0.016864045 | AJ26: 0.035970745 | AK26: 0.02521354 | AL26: 0.022795497 | AM26: 0.027857936 | AN26: 0.026036364 | AO26: 0.031598107 | AP26: 0.025175083 | AQ26: 0.022171946 | AR26: 0.025125363 | AS26: 0.038560411 | AT26: 0.037918041 | AU26: 0.029844173 | AV26: 0.027054981 | AW26: 0.035179283 | AX26: 0.048673698 | AY26: 0.036886465 | AZ26: 0.037402344 | BA26: 0.028457799 | BB26: 0.024481152 | BC26: 0.038063635 | BD26: 0.029862244 | BE26: 0.028267183 | BF26: 0.033096447 | BG26: 0.038095238 | BH26: 0.028917197 | BI26: 0.046396081 | BJ26: 0.03065799 | BK26: 0 | BL26: 0 | BM26: 0 | BN26: 0.049138713 | BO26: 0.039652677 | BP26: 0.039696439 | BQ26: 0.02739408 | BR26: 0.031515152 | BS26: 0.027754862 | BT26: =+VLOOKUP(CONCATENATE($A26,BT$25),Datos!$B:$AV,42,FALSE) -> 0.02599492 | BU26: =+VLOOKUP(CONCATENATE($A26,BU$25),Datos!$B:$AV,42,FALSE) -> 0.027424094 | BV26: =+VLOOKUP(CONCATENATE($A26,BV$25),Datos!$B:$AV,42,FALSE) -> 0.030687204 | BW26: =+VLOOKUP(CONCATENATE($A26,BW$25),Datos!$B:$AV,42,FALSE) -> 0.025044092 | BX26: =+VLOOKUP(CONCATENATE($A26,BX$25),Datos!$B:$AV,42,FALSE) -> 0.057340242 | BY26: =+VLOOKUP(CONCATENATE($A26,BY$25),Datos!$B:$AV,42,FALSE) -> 0.021561917 | BZ26: =+VLOOKUP(CONCATENATE($A26,BZ$25),Datos!$B:$AV,42,FALSE) -> 0.045856296 | CA26: =+VLOOKUP(CONCATENATE($A26,CA$25),Datos!$B:$AV,42,FALSE) -> 0.042589532 | ... CD26: =+VLOOKUP(CONCATENATE($A26,CD$25),Datos!$B:$AV,42,FALSE) -> 0.029253112 | CE26: =IFERROR(VLOOKUP(CONCATENATE($A26,CE$25),Datos!$B:$AV,42,FALSE),"0") -> 0.031699478 | CF26: =IFERROR(VLOOKUP(CONCATENATE($A26,CF$25),Datos!$B:$AV,42,FALSE),"0") -> 0.040053405 | CG26: =IFERROR(VLOOKUP(CONCATENATE($A26,CG$25),Datos!$B:$AV,42,FALSE),"0") -> 0.029228437 | CH26: =IFERROR(VLOOKUP(CONCATENATE($A26,CH$25),Datos!$B:$AV,42,FALSE),"0") -> 0.033483399 | CI26: =IFERROR(VLOOKUP(CONCATENATE($A26,CI$25),Datos!$B:$AV,42,FALSE),"0") -> 0.03621118 | CJ26: =IFERROR(VLOOKUP(CONCATENATE($A26,CJ$25),Datos!$B:$AV,42,FALSE),"0") -> 0.0291834 | CK26: =IFERROR(VLOOKUP(CONCATENATE($A26,CK$25),Datos!$B:$AV,42,FALSE),"0") -> 0.036029412 | CL26: =IFERROR(VLOOKUP(CONCATENATE($A26,CL$25),Datos!$B:$AV,42,FALSE),"0") -> 0.031538788 | ... DA26: =IFERROR(VLOOKUP(CONCATENATE($A26,DA$25),Datos!$B:$AV,42,FALSE),"0") -> 0.063490099
